<?xml version="1.0" ?>
<!-- =================================================================================== -->
<!-- |    This document was autogenerated by xacro from smartcar.urdf.xacro            | -->
<!-- |    EDITING THIS FILE BY HAND IS NOT RECOMMENDED                                 | -->
<!-- =================================================================================== -->
<robot name="smart_car">
  <!-- Base link -->
  <link name="base_link">
    <visual>
      <geometry>
        <box size="0.257 0.17 0.1"/>
      </geometry>
      <material name="blue">
        <color rgba="0 0 1 1"/>
      </material>
    </visual>
  </link>
  <!-- Chassis link -->
  <link name="chassis_link">
    <visual>
      <geometry>
        <box size="0.257 0.17 0.1"/>
      </geometry>
      <material name="grey">
        <color rgba="0.5 0.5 0.5 1"/>
      </material>
    </visual>
  </link>
  <!-- Base footprint -->
  <link name="base_footprint">
    <visual>
      <geometry>
        <box size="0.257 0.17 0.01"/>
      </geometry>
      <material name="transparent">
        <color rgba="0 0 0 0"/>
      </material>
    </visual>
  </link>
  <!-- Joint to connect base_footprint to base_link -->
  <joint name="base_footprint_joint" type="fixed">
    <parent link="base_footprint"/>
    <child link="base_link"/>
    <origin xyz="0 0 0"/>
    <axis xyz="0 0 1"/>
  </joint>
  <!-- Wheels -->
  <link name="back_left_wheel">
    <visual>
      <geometry>
        <cylinder length="0.025" radius="0.032"/>
      </geometry>
      <material name="black">
        <color rgba="0 0 0 1"/>
      </material>
    </visual>
  </link>
  <link name="back_right_wheel">
    <visual>
      <geometry>
        <cylinder length="0.025" radius="0.032"/>
      </geometry>
      <material name="black">
        <color rgba="0 0 0 1"/>
      </material>
    </visual>
  </link>
  <link name="front_left_wheel">
    <visual>
      <geometry>
        <cylinder length="0.025" radius="0.032"/>
      </geometry>
      <material name="black">
        <color rgba="0 0 0 1"/>
      </material>
    </visual>
  </link>
  <link name="front_right_wheel">
    <visual>
      <geometry>
        <cylinder length="0.025" radius="0.032"/>
      </geometry>
      <material name="black">
        <color rgba="0 0 0 1"/>
      </material>
    </visual>
  </link>
  <!-- Joints -->
  <joint name="back_left_wheel_joint" type="continuous">
    <parent link="base_link"/>
    <child link="back_left_wheel"/>
    <origin xyz="0 0.085 0"/>
    <axis xyz="0 1 0"/>
  </joint>
  <joint name="back_right_wheel_joint" type="continuous">
    <parent link="base_link"/>
    <child link="back_right_wheel"/>
    <origin xyz="0 -0.085 0"/>
    <axis xyz="0 1 0"/>
  </joint>
  <joint name="front_left_wheel_steer_joint" type="continuous">
    <parent link="base_link"/>
    <child link="front_left_wheel"/>
    <origin xyz="0.1285 0.085 0"/>
    <axis xyz="0 1 0"/>
  </joint>
  <joint name="front_left_wheel_joint" type="continuous">
    <parent link="base_link"/>
    <child link="front_left_wheel"/>
    <origin xyz="0.1285 0.085 0"/>
    <axis xyz="0 1 0"/>
  </joint>
  <joint name="front_right_wheel_steer_joint" type="continuous">
    <parent link="base_link"/>
    <child link="front_right_wheel"/>
    <origin xyz="0.1285 -0.085 0"/>
    <axis xyz="0 1 0"/>
  </joint>
  <joint name="front_right_wheel_joint" type="continuous">
    <parent link="base_link"/>
    <child link="front_right_wheel"/>
    <origin xyz="0.1285 -0.085 0"/>
    <axis xyz="0 1 0"/>
  </joint>
</robot>
